[2025-09-03T16:24:18.918+0000] {local_task_job_runner.py:120} INFO - ::group::Pre task execution logs
[2025-09-03T16:24:18.990+0000] {taskinstance.py:2076} INFO - Dependencies all met for dep_context=non-requeueable deps ti=<TaskInstance: test_s3_conn.test_s3 manual__2025-09-03T16:24:15.592732+00:00 [queued]>
[2025-09-03T16:24:19.025+0000] {taskinstance.py:2076} INFO - Dependencies all met for dep_context=requeueable deps ti=<TaskInstance: test_s3_conn.test_s3 manual__2025-09-03T16:24:15.592732+00:00 [queued]>
[2025-09-03T16:24:19.036+0000] {taskinstance.py:2306} INFO - Starting attempt 1 of 1
[2025-09-03T16:24:19.109+0000] {taskinstance.py:2330} INFO - Executing <Task(PythonOperator): test_s3> on 2025-09-03 16:24:15.592732+00:00
[2025-09-03T16:24:19.131+0000] {standard_task_runner.py:63} INFO - Started process 448 to run task
[2025-09-03T16:24:19.143+0000] {standard_task_runner.py:90} INFO - Running: ['***', 'tasks', 'run', 'test_s3_conn', 'test_s3', 'manual__2025-09-03T16:24:15.592732+00:00', '--job-id', '172', '--raw', '--subdir', 'DAGS_FOLDER/S3_dag.py', '--cfg-path', '/tmp/tmpx7v9azsb']
[2025-09-03T16:24:19.157+0000] {standard_task_runner.py:91} INFO - Job 172: Subtask test_s3
[2025-09-03T16:24:19.204+0000] {logging_mixin.py:188} WARNING - /home/***/.local/lib/python3.10/site-packages/***/settings.py:195 DeprecationWarning: The sql_alchemy_conn option in [core] has been moved to the sql_alchemy_conn option in [database] - the old setting has been used, but please update your config.
[2025-09-03T16:24:19.302+0000] {task_command.py:426} INFO - Running <TaskInstance: test_s3_conn.test_s3 manual__2025-09-03T16:24:15.592732+00:00 [running]> on host 6aba05baf296
[2025-09-03T16:24:19.446+0000] {taskinstance.py:2648} INFO - Exporting env vars: AIRFLOW_CTX_DAG_OWNER='***' AIRFLOW_CTX_DAG_ID='test_s3_conn' AIRFLOW_CTX_TASK_ID='test_s3' AIRFLOW_CTX_EXECUTION_DATE='2025-09-03T16:24:15.592732+00:00' AIRFLOW_CTX_TRY_NUMBER='1' AIRFLOW_CTX_DAG_RUN_ID='manual__2025-09-03T16:24:15.592732+00:00'
[2025-09-03T16:24:19.447+0000] {taskinstance.py:430} INFO - ::endgroup::
[2025-09-03T16:24:19.464+0000] {taskinstance.py:441} INFO - ::group::Post task execution logs
[2025-09-03T16:24:19.465+0000] {taskinstance.py:2905} ERROR - Task failed with exception
Traceback (most recent call last):
  File "/home/airflow/.local/lib/python3.10/site-packages/airflow/models/taskinstance.py", line 465, in _execute_task
    result = _execute_callable(context=context, **execute_callable_kwargs)
  File "/home/airflow/.local/lib/python3.10/site-packages/airflow/models/taskinstance.py", line 432, in _execute_callable
    return execute_callable(context=context, **execute_callable_kwargs)
  File "/home/airflow/.local/lib/python3.10/site-packages/airflow/models/baseoperator.py", line 401, in wrapper
    return func(self, *args, **kwargs)
  File "/home/airflow/.local/lib/python3.10/site-packages/airflow/operators/python.py", line 235, in execute
    return_value = self.execute_callable()
  File "/home/airflow/.local/lib/python3.10/site-packages/airflow/operators/python.py", line 252, in execute_callable
    return self.python_callable(*self.op_args, **self.op_kwargs)
  File "/opt/airflow/dags/S3_dag.py", line 8, in test_s3_connection
    buckets = hook.list_buckets()
AttributeError: 'S3Hook' object has no attribute 'list_buckets'
[2025-09-03T16:24:19.482+0000] {taskinstance.py:1206} INFO - Marking task as FAILED. dag_id=test_s3_conn, task_id=test_s3, run_id=manual__2025-09-03T16:24:15.592732+00:00, execution_date=20250903T162415, start_date=20250903T162418, end_date=20250903T162419
[2025-09-03T16:24:19.502+0000] {standard_task_runner.py:110} ERROR - Failed to execute job 172 for task test_s3 ('S3Hook' object has no attribute 'list_buckets'; 448)
[2025-09-03T16:24:20.095+0000] {local_task_job_runner.py:240} INFO - Task exited with return code 1
[2025-09-03T16:24:20.137+0000] {taskinstance.py:3503} INFO - 0 downstream tasks scheduled from follow-on schedule check
[2025-09-03T16:24:20.141+0000] {local_task_job_runner.py:222} INFO - ::endgroup::
