[2025-08-28T08:25:39.307+0000] {local_task_job_runner.py:120} INFO - ::group::Pre task execution logs
[2025-08-28T08:25:39.805+0000] {taskinstance.py:2076} INFO - Dependencies all met for dep_context=non-requeueable deps ti=<TaskInstance: ecommerce_pipeline.sales_per_country manual__2025-08-28T07:21:41.282152+00:00 [queued]>
[2025-08-28T08:25:39.882+0000] {taskinstance.py:2076} INFO - Dependencies all met for dep_context=requeueable deps ti=<TaskInstance: ecommerce_pipeline.sales_per_country manual__2025-08-28T07:21:41.282152+00:00 [queued]>
[2025-08-28T08:25:39.901+0000] {taskinstance.py:2306} INFO - Starting attempt 3 of 4
[2025-08-28T08:25:40.037+0000] {taskinstance.py:2330} INFO - Executing <Task(BashOperator): sales_per_country> on 2025-08-28 07:21:41.282152+00:00
[2025-08-28T08:25:40.110+0000] {standard_task_runner.py:90} INFO - Running: ['***', 'tasks', 'run', 'ecommerce_pipeline', 'sales_per_country', 'manual__2025-08-28T07:21:41.282152+00:00', '--job-id', '101', '--raw', '--subdir', 'DAGS_FOLDER/ecommerce_pipeline_dag.py', '--cfg-path', '/tmp/tmpg_181ubw']
[2025-08-28T08:25:40.212+0000] {standard_task_runner.py:91} INFO - Job 101: Subtask sales_per_country
[2025-08-28T08:25:40.062+0000] {standard_task_runner.py:63} INFO - Started process 934 to run task
[2025-08-28T08:25:40.425+0000] {logging_mixin.py:188} WARNING - /home/***/.local/lib/python3.10/site-packages/***/settings.py:195 DeprecationWarning: The sql_alchemy_conn option in [core] has been moved to the sql_alchemy_conn option in [database] - the old setting has been used, but please update your config.
[2025-08-28T08:25:40.547+0000] {task_command.py:426} INFO - Running <TaskInstance: ecommerce_pipeline.sales_per_country manual__2025-08-28T07:21:41.282152+00:00 [running]> on host 6aba05baf296
[2025-08-28T08:25:40.957+0000] {taskinstance.py:2648} INFO - Exporting env vars: AIRFLOW_CTX_DAG_OWNER='arel' AIRFLOW_CTX_DAG_ID='ecommerce_pipeline' AIRFLOW_CTX_TASK_ID='sales_per_country' AIRFLOW_CTX_EXECUTION_DATE='2025-08-28T07:21:41.282152+00:00' AIRFLOW_CTX_TRY_NUMBER='3' AIRFLOW_CTX_DAG_RUN_ID='manual__2025-08-28T07:21:41.282152+00:00'
[2025-08-28T08:25:40.974+0000] {taskinstance.py:430} INFO - ::endgroup::
[2025-08-28T08:25:41.032+0000] {subprocess.py:63} INFO - Tmp dir root location: /tmp
[2025-08-28T08:25:41.036+0000] {subprocess.py:75} INFO - Running command: ['/usr/bin/bash', '-c', 'psql -h postgres -U *** -d *** -f /opt/***/sql/sales_per_country.sql']
[2025-08-28T08:25:41.066+0000] {subprocess.py:86} INFO - Output:
[2025-08-28T08:25:41.320+0000] {subprocess.py:93} INFO - Password for user ***:
[2025-08-28T08:25:41.326+0000] {subprocess.py:93} INFO - psql: error: connection to server at "postgres" (172.20.0.2), port 5432 failed: fe_sendauth: no password supplied
[2025-08-28T08:25:41.330+0000] {subprocess.py:97} INFO - Command exited with return code 2
[2025-08-28T08:25:41.335+0000] {taskinstance.py:441} INFO - ::group::Post task execution logs
[2025-08-28T08:25:41.358+0000] {taskinstance.py:2905} ERROR - Task failed with exception
Traceback (most recent call last):
  File "/home/airflow/.local/lib/python3.10/site-packages/airflow/models/taskinstance.py", line 465, in _execute_task
    result = _execute_callable(context=context, **execute_callable_kwargs)
  File "/home/airflow/.local/lib/python3.10/site-packages/airflow/models/taskinstance.py", line 432, in _execute_callable
    return execute_callable(context=context, **execute_callable_kwargs)
  File "/home/airflow/.local/lib/python3.10/site-packages/airflow/models/baseoperator.py", line 401, in wrapper
    return func(self, *args, **kwargs)
  File "/home/airflow/.local/lib/python3.10/site-packages/airflow/operators/bash.py", line 243, in execute
    raise AirflowException(
airflow.exceptions.AirflowException: Bash command failed. The command returned a non-zero exit code 2.
[2025-08-28T08:25:41.369+0000] {taskinstance.py:1206} INFO - Marking task as UP_FOR_RETRY. dag_id=ecommerce_pipeline, task_id=sales_per_country, run_id=manual__2025-08-28T07:21:41.282152+00:00, execution_date=20250828T072141, start_date=20250828T082539, end_date=20250828T082541
[2025-08-28T08:25:41.480+0000] {standard_task_runner.py:110} ERROR - Failed to execute job 101 for task sales_per_country (Bash command failed. The command returned a non-zero exit code 2.; 934)
[2025-08-28T08:25:41.527+0000] {local_task_job_runner.py:240} INFO - Task exited with return code 1
[2025-08-28T08:25:41.567+0000] {taskinstance.py:3503} INFO - 0 downstream tasks scheduled from follow-on schedule check
[2025-08-28T08:25:41.620+0000] {local_task_job_runner.py:222} INFO - ::endgroup::
