[2025-08-27T17:10:30.955+0000] {local_task_job_runner.py:120} INFO - ::group::Pre task execution logs
[2025-08-27T17:10:31.024+0000] {taskinstance.py:2076} INFO - Dependencies all met for dep_context=non-requeueable deps ti=<TaskInstance: ecommerce_pipeline.load_data scheduled__2025-08-26T00:00:00+00:00 [queued]>
[2025-08-27T17:10:31.050+0000] {taskinstance.py:2076} INFO - Dependencies all met for dep_context=requeueable deps ti=<TaskInstance: ecommerce_pipeline.load_data scheduled__2025-08-26T00:00:00+00:00 [queued]>
[2025-08-27T17:10:31.051+0000] {taskinstance.py:2306} INFO - Starting attempt 2 of 2
[2025-08-27T17:10:31.112+0000] {taskinstance.py:2330} INFO - Executing <Task(PythonOperator): load_data> on 2025-08-26 00:00:00+00:00
[2025-08-27T17:10:31.141+0000] {standard_task_runner.py:90} INFO - Running: ['***', 'tasks', 'run', 'ecommerce_pipeline', 'load_data', 'scheduled__2025-08-26T00:00:00+00:00', '--job-id', '8', '--raw', '--subdir', 'DAGS_FOLDER/ecommerce_pipeline_dag.py', '--cfg-path', '/tmp/tmphzs_an50']
[2025-08-27T17:10:31.127+0000] {standard_task_runner.py:63} INFO - Started process 610 to run task
[2025-08-27T17:10:31.147+0000] {standard_task_runner.py:91} INFO - Job 8: Subtask load_data
[2025-08-27T17:10:31.275+0000] {logging_mixin.py:188} WARNING - /home/***/.local/lib/python3.10/site-packages/***/settings.py:195 DeprecationWarning: The sql_alchemy_conn option in [core] has been moved to the sql_alchemy_conn option in [database] - the old setting has been used, but please update your config.
[2025-08-27T17:10:31.486+0000] {task_command.py:426} INFO - Running <TaskInstance: ecommerce_pipeline.load_data scheduled__2025-08-26T00:00:00+00:00 [running]> on host ebefcdbd1d31
[2025-08-27T17:10:31.901+0000] {taskinstance.py:2648} INFO - Exporting env vars: AIRFLOW_CTX_DAG_OWNER='arel' AIRFLOW_CTX_DAG_ID='ecommerce_pipeline' AIRFLOW_CTX_TASK_ID='load_data' AIRFLOW_CTX_EXECUTION_DATE='2025-08-26T00:00:00+00:00' AIRFLOW_CTX_TRY_NUMBER='2' AIRFLOW_CTX_DAG_RUN_ID='scheduled__2025-08-26T00:00:00+00:00'
[2025-08-27T17:10:31.904+0000] {taskinstance.py:430} INFO - ::endgroup::
[2025-08-27T17:10:42.361+0000] {taskinstance.py:441} INFO - ::group::Post task execution logs
[2025-08-27T17:10:42.362+0000] {taskinstance.py:2905} ERROR - Task failed with exception
Traceback (most recent call last):
  File "/home/airflow/.local/lib/python3.10/site-packages/airflow/models/taskinstance.py", line 465, in _execute_task
    result = _execute_callable(context=context, **execute_callable_kwargs)
  File "/home/airflow/.local/lib/python3.10/site-packages/airflow/models/taskinstance.py", line 432, in _execute_callable
    return execute_callable(context=context, **execute_callable_kwargs)
  File "/home/airflow/.local/lib/python3.10/site-packages/airflow/models/baseoperator.py", line 401, in wrapper
    return func(self, *args, **kwargs)
  File "/home/airflow/.local/lib/python3.10/site-packages/airflow/operators/python.py", line 235, in execute
    return_value = self.execute_callable()
  File "/home/airflow/.local/lib/python3.10/site-packages/airflow/operators/python.py", line 252, in execute_callable
    return self.python_callable(*self.op_args, **self.op_kwargs)
  File "/opt/airflow/dags/ecommerce_pipeline_dag.py", line 9, in run_load_data
    subprocess.run(["python3", "/opt/airflow/etl/load_data.py"], check=True)
  File "/usr/local/lib/python3.10/subprocess.py", line 526, in run
    raise CalledProcessError(retcode, process.args,
subprocess.CalledProcessError: Command '['python3', '/opt/airflow/etl/load_data.py']' returned non-zero exit status 1.
[2025-08-27T17:10:42.396+0000] {taskinstance.py:1206} INFO - Marking task as FAILED. dag_id=ecommerce_pipeline, task_id=load_data, run_id=scheduled__2025-08-26T00:00:00+00:00, execution_date=20250826T000000, start_date=20250827T171031, end_date=20250827T171042
[2025-08-27T17:10:42.509+0000] {standard_task_runner.py:110} ERROR - Failed to execute job 8 for task load_data (Command '['python3', '/opt/airflow/etl/load_data.py']' returned non-zero exit status 1.; 610)
[2025-08-27T17:10:42.553+0000] {local_task_job_runner.py:240} INFO - Task exited with return code 1
[2025-08-27T17:10:42.604+0000] {taskinstance.py:3503} INFO - 0 downstream tasks scheduled from follow-on schedule check
[2025-08-27T17:10:42.650+0000] {local_task_job_runner.py:222} INFO - ::endgroup::
