[2025-08-28T07:45:13.735+0000] {local_task_job_runner.py:120} INFO - ::group::Pre task execution logs
[2025-08-28T07:45:13.838+0000] {taskinstance.py:2076} INFO - Dependencies all met for dep_context=non-requeueable deps ti=<TaskInstance: ecommerce_pipeline.daily_sales manual__2025-08-28T07:21:41.282152+00:00 [queued]>
[2025-08-28T07:45:13.855+0000] {taskinstance.py:2076} INFO - Dependencies all met for dep_context=requeueable deps ti=<TaskInstance: ecommerce_pipeline.daily_sales manual__2025-08-28T07:21:41.282152+00:00 [queued]>
[2025-08-28T07:45:13.856+0000] {taskinstance.py:2306} INFO - Starting attempt 4 of 4
[2025-08-28T07:45:13.883+0000] {taskinstance.py:2330} INFO - Executing <Task(BashOperator): daily_sales> on 2025-08-28 07:21:41.282152+00:00
[2025-08-28T07:45:13.890+0000] {standard_task_runner.py:63} INFO - Started process 1724 to run task
[2025-08-28T07:45:13.895+0000] {standard_task_runner.py:90} INFO - Running: ['***', 'tasks', 'run', 'ecommerce_pipeline', 'daily_sales', 'manual__2025-08-28T07:21:41.282152+00:00', '--job-id', '94', '--raw', '--subdir', 'DAGS_FOLDER/ecommerce_pipeline_dag.py', '--cfg-path', '/tmp/tmpfcpggall']
[2025-08-28T07:45:13.897+0000] {standard_task_runner.py:91} INFO - Job 94: Subtask daily_sales
[2025-08-28T07:45:13.921+0000] {logging_mixin.py:188} WARNING - /home/***/.local/lib/python3.10/site-packages/***/settings.py:195 DeprecationWarning: The sql_alchemy_conn option in [core] has been moved to the sql_alchemy_conn option in [database] - the old setting has been used, but please update your config.
[2025-08-28T07:45:14.013+0000] {task_command.py:426} INFO - Running <TaskInstance: ecommerce_pipeline.daily_sales manual__2025-08-28T07:21:41.282152+00:00 [running]> on host 9b893e28b5b2
[2025-08-28T07:45:14.236+0000] {taskinstance.py:2648} INFO - Exporting env vars: AIRFLOW_CTX_DAG_OWNER='arel' AIRFLOW_CTX_DAG_ID='ecommerce_pipeline' AIRFLOW_CTX_TASK_ID='daily_sales' AIRFLOW_CTX_EXECUTION_DATE='2025-08-28T07:21:41.282152+00:00' AIRFLOW_CTX_TRY_NUMBER='4' AIRFLOW_CTX_DAG_RUN_ID='manual__2025-08-28T07:21:41.282152+00:00'
[2025-08-28T07:45:14.238+0000] {taskinstance.py:430} INFO - ::endgroup::
[2025-08-28T07:45:14.260+0000] {subprocess.py:63} INFO - Tmp dir root location: /tmp
[2025-08-28T07:45:14.262+0000] {subprocess.py:75} INFO - Running command: ['/usr/bin/bash', '-c', 'PGPASSWORD=*** psql -h postgres -U *** -d *** -f /opt/***/sql/daily_sales.sql']
[2025-08-28T07:45:14.297+0000] {subprocess.py:86} INFO - Output:
[2025-08-28T07:45:14.400+0000] {subprocess.py:93} INFO - psql: error: /opt/***/sql/daily_sales.sql: No such file or directory
[2025-08-28T07:45:14.405+0000] {subprocess.py:97} INFO - Command exited with return code 1
[2025-08-28T07:45:14.407+0000] {taskinstance.py:441} INFO - ::group::Post task execution logs
[2025-08-28T07:45:14.435+0000] {taskinstance.py:2905} ERROR - Task failed with exception
Traceback (most recent call last):
  File "/home/airflow/.local/lib/python3.10/site-packages/airflow/models/taskinstance.py", line 465, in _execute_task
    result = _execute_callable(context=context, **execute_callable_kwargs)
  File "/home/airflow/.local/lib/python3.10/site-packages/airflow/models/taskinstance.py", line 432, in _execute_callable
    return execute_callable(context=context, **execute_callable_kwargs)
  File "/home/airflow/.local/lib/python3.10/site-packages/airflow/models/baseoperator.py", line 401, in wrapper
    return func(self, *args, **kwargs)
  File "/home/airflow/.local/lib/python3.10/site-packages/airflow/operators/bash.py", line 243, in execute
    raise AirflowException(
airflow.exceptions.AirflowException: Bash command failed. The command returned a non-zero exit code 1.
[2025-08-28T07:45:14.443+0000] {taskinstance.py:1206} INFO - Marking task as FAILED. dag_id=ecommerce_pipeline, task_id=daily_sales, run_id=manual__2025-08-28T07:21:41.282152+00:00, execution_date=20250828T072141, start_date=20250828T074513, end_date=20250828T074514
[2025-08-28T07:45:14.475+0000] {standard_task_runner.py:110} ERROR - Failed to execute job 94 for task daily_sales (Bash command failed. The command returned a non-zero exit code 1.; 1724)
[2025-08-28T07:45:14.505+0000] {local_task_job_runner.py:240} INFO - Task exited with return code 1
[2025-08-28T07:45:14.528+0000] {taskinstance.py:3503} INFO - 0 downstream tasks scheduled from follow-on schedule check
[2025-08-28T07:45:14.531+0000] {local_task_job_runner.py:222} INFO - ::endgroup::
